2024-06-11 23:32:13,128 - logger - ERROR - Error occurred while executing custom query: <urlopen error [Errno 111] Connection refused>
Traceback (most recent call last):
  File "/lustre06/project/6045755/omij/Chatbot-Resources/benchmark/kg/kg/kg.py", line 463, in shoot_custom_query
    caching_answer = sparql.query().convert()
                     ^^^^^^^^^^^^^^
  File "/home/omij/.local/lib/python3.11/site-packages/SPARQLWrapper/Wrapper.py", line 960, in query
    return QueryResult(self._query())
                       ^^^^^^^^^^^^^
  File "/home/omij/.local/lib/python3.11/site-packages/SPARQLWrapper/Wrapper.py", line 926, in _query
    response = urlopener(request)
               ^^^^^^^^^^^^^^^^^^
  File "/cvmfs/soft.computecanada.ca/easybuild/software/2023/x86-64-v3/Compiler/gcccore/python/3.11.5/lib/python3.11/urllib/request.py", line 216, in urlopen
    return opener.open(url, data, timeout)
           ^^^^^^^^^^^^^^^^^^^^^^^^^^^^^^^
  File "/cvmfs/soft.computecanada.ca/easybuild/software/2023/x86-64-v3/Compiler/gcccore/python/3.11.5/lib/python3.11/urllib/request.py", line 519, in open
    response = self._open(req, data)
               ^^^^^^^^^^^^^^^^^^^^^
  File "/cvmfs/soft.computecanada.ca/easybuild/software/2023/x86-64-v3/Compiler/gcccore/python/3.11.5/lib/python3.11/urllib/request.py", line 536, in _open
    result = self._call_chain(self.handle_open, protocol, protocol +
             ^^^^^^^^^^^^^^^^^^^^^^^^^^^^^^^^^^^^^^^^^^^^^^^^^^^^^^^
  File "/cvmfs/soft.computecanada.ca/easybuild/software/2023/x86-64-v3/Compiler/gcccore/python/3.11.5/lib/python3.11/urllib/request.py", line 496, in _call_chain
    result = func(*args)
             ^^^^^^^^^^^
  File "/cvmfs/soft.computecanada.ca/easybuild/software/2023/x86-64-v3/Compiler/gcccore/python/3.11.5/lib/python3.11/urllib/request.py", line 1377, in http_open
    return self.do_open(http.client.HTTPConnection, req)
           ^^^^^^^^^^^^^^^^^^^^^^^^^^^^^^^^^^^^^^^^^^^^^
  File "/cvmfs/soft.computecanada.ca/easybuild/software/2023/x86-64-v3/Compiler/gcccore/python/3.11.5/lib/python3.11/urllib/request.py", line 1352, in do_open
    r = h.getresponse()
        ^^^^^^^^^^^^^^^
  File "/cvmfs/soft.computecanada.ca/easybuild/software/2023/x86-64-v3/Compiler/gcccore/python/3.11.5/lib/python3.11/http/client.py", line 1378, in getresponse
    response.begin()
  File "/cvmfs/soft.computecanada.ca/easybuild/software/2023/x86-64-v3/Compiler/gcccore/python/3.11.5/lib/python3.11/http/client.py", line 318, in begin
    version, status, reason = self._read_status()
                              ^^^^^^^^^^^^^^^^^^^
  File "/cvmfs/soft.computecanada.ca/easybuild/software/2023/x86-64-v3/Compiler/gcccore/python/3.11.5/lib/python3.11/http/client.py", line 287, in _read_status
    raise RemoteDisconnected("Remote end closed connection without"
http.client.RemoteDisconnected: Remote end closed connection without response

During handling of the above exception, another exception occurred:

Traceback (most recent call last):
  File "/cvmfs/soft.computecanada.ca/easybuild/software/2023/x86-64-v3/Compiler/gcccore/python/3.11.5/lib/python3.11/urllib/request.py", line 1348, in do_open
    h.request(req.get_method(), req.selector, req.data, headers,
  File "/cvmfs/soft.computecanada.ca/easybuild/software/2023/x86-64-v3/Compiler/gcccore/python/3.11.5/lib/python3.11/http/client.py", line 1286, in request
    self._send_request(method, url, body, headers, encode_chunked)
  File "/cvmfs/soft.computecanada.ca/easybuild/software/2023/x86-64-v3/Compiler/gcccore/python/3.11.5/lib/python3.11/http/client.py", line 1332, in _send_request
    self.endheaders(body, encode_chunked=encode_chunked)
  File "/cvmfs/soft.computecanada.ca/easybuild/software/2023/x86-64-v3/Compiler/gcccore/python/3.11.5/lib/python3.11/http/client.py", line 1281, in endheaders
    self._send_output(message_body, encode_chunked=encode_chunked)
  File "/cvmfs/soft.computecanada.ca/easybuild/software/2023/x86-64-v3/Compiler/gcccore/python/3.11.5/lib/python3.11/http/client.py", line 1041, in _send_output
    self.send(msg)
  File "/cvmfs/soft.computecanada.ca/easybuild/software/2023/x86-64-v3/Compiler/gcccore/python/3.11.5/lib/python3.11/http/client.py", line 979, in send
    self.connect()
  File "/cvmfs/soft.computecanada.ca/easybuild/software/2023/x86-64-v3/Compiler/gcccore/python/3.11.5/lib/python3.11/http/client.py", line 945, in connect
    self.sock = self._create_connection(
                ^^^^^^^^^^^^^^^^^^^^^^^^
  File "/cvmfs/soft.computecanada.ca/easybuild/software/2023/x86-64-v3/Compiler/gcccore/python/3.11.5/lib/python3.11/socket.py", line 851, in create_connection
    raise exceptions[0]
  File "/cvmfs/soft.computecanada.ca/easybuild/software/2023/x86-64-v3/Compiler/gcccore/python/3.11.5/lib/python3.11/socket.py", line 836, in create_connection
    sock.connect(sa)
ConnectionRefusedError: [Errno 111] Connection refused

During handling of the above exception, another exception occurred:

Traceback (most recent call last):
  File "/lustre06/project/6045755/omij/Chatbot-Resources/benchmark/kg/kg/kg.py", line 468, in shoot_custom_query
    caching_answer = sparql.query().convert()
                     ^^^^^^^^^^^^^^
  File "/home/omij/.local/lib/python3.11/site-packages/SPARQLWrapper/Wrapper.py", line 960, in query
    return QueryResult(self._query())
                       ^^^^^^^^^^^^^
  File "/home/omij/.local/lib/python3.11/site-packages/SPARQLWrapper/Wrapper.py", line 926, in _query
    response = urlopener(request)
               ^^^^^^^^^^^^^^^^^^
  File "/cvmfs/soft.computecanada.ca/easybuild/software/2023/x86-64-v3/Compiler/gcccore/python/3.11.5/lib/python3.11/urllib/request.py", line 216, in urlopen
    return opener.open(url, data, timeout)
           ^^^^^^^^^^^^^^^^^^^^^^^^^^^^^^^
  File "/cvmfs/soft.computecanada.ca/easybuild/software/2023/x86-64-v3/Compiler/gcccore/python/3.11.5/lib/python3.11/urllib/request.py", line 519, in open
    response = self._open(req, data)
               ^^^^^^^^^^^^^^^^^^^^^
  File "/cvmfs/soft.computecanada.ca/easybuild/software/2023/x86-64-v3/Compiler/gcccore/python/3.11.5/lib/python3.11/urllib/request.py", line 536, in _open
    result = self._call_chain(self.handle_open, protocol, protocol +
             ^^^^^^^^^^^^^^^^^^^^^^^^^^^^^^^^^^^^^^^^^^^^^^^^^^^^^^^
  File "/cvmfs/soft.computecanada.ca/easybuild/software/2023/x86-64-v3/Compiler/gcccore/python/3.11.5/lib/python3.11/urllib/request.py", line 496, in _call_chain
    result = func(*args)
             ^^^^^^^^^^^
  File "/cvmfs/soft.computecanada.ca/easybuild/software/2023/x86-64-v3/Compiler/gcccore/python/3.11.5/lib/python3.11/urllib/request.py", line 1377, in http_open
    return self.do_open(http.client.HTTPConnection, req)
           ^^^^^^^^^^^^^^^^^^^^^^^^^^^^^^^^^^^^^^^^^^^^^
  File "/cvmfs/soft.computecanada.ca/easybuild/software/2023/x86-64-v3/Compiler/gcccore/python/3.11.5/lib/python3.11/urllib/request.py", line 1351, in do_open
    raise URLError(err)
urllib.error.URLError: <urlopen error [Errno 111] Connection refused>
2024-06-11 23:32:13,240 - logger - ERROR - Error occurred while extracting subgraph: kg.kg.kg.SparqlQueryResponse() argument after ** must be a mapping, not NoneType
Traceback (most recent call last):
  File "/lustre06/project/6045755/omij/Chatbot-Resources/benchmark/kg/kg/kg.py", line 534, in subgraph_extractor
    q_response = SparqlQueryResponse(**result)
                 ^^^^^^^^^^^^^^^^^^^^^^^^^^^^^
TypeError: kg.kg.kg.SparqlQueryResponse() argument after ** must be a mapping, not NoneType
2024-06-11 23:50:37,282 - logger - ERROR - Error occurred while executing custom query: <urlopen error [Errno 111] Connection refused>
Traceback (most recent call last):
  File "/lustre06/project/6045755/omij/Chatbot-Resources/benchmark/kg/kg/kg.py", line 463, in shoot_custom_query
    caching_answer = sparql.query().convert()
                     ^^^^^^^^^^^^^^
  File "/home/omij/.local/lib/python3.11/site-packages/SPARQLWrapper/Wrapper.py", line 960, in query
    return QueryResult(self._query())
                       ^^^^^^^^^^^^^
  File "/home/omij/.local/lib/python3.11/site-packages/SPARQLWrapper/Wrapper.py", line 926, in _query
    response = urlopener(request)
               ^^^^^^^^^^^^^^^^^^
  File "/cvmfs/soft.computecanada.ca/easybuild/software/2023/x86-64-v3/Compiler/gcccore/python/3.11.5/lib/python3.11/urllib/request.py", line 216, in urlopen
    return opener.open(url, data, timeout)
           ^^^^^^^^^^^^^^^^^^^^^^^^^^^^^^^
  File "/cvmfs/soft.computecanada.ca/easybuild/software/2023/x86-64-v3/Compiler/gcccore/python/3.11.5/lib/python3.11/urllib/request.py", line 519, in open
    response = self._open(req, data)
               ^^^^^^^^^^^^^^^^^^^^^
  File "/cvmfs/soft.computecanada.ca/easybuild/software/2023/x86-64-v3/Compiler/gcccore/python/3.11.5/lib/python3.11/urllib/request.py", line 536, in _open
    result = self._call_chain(self.handle_open, protocol, protocol +
             ^^^^^^^^^^^^^^^^^^^^^^^^^^^^^^^^^^^^^^^^^^^^^^^^^^^^^^^
  File "/cvmfs/soft.computecanada.ca/easybuild/software/2023/x86-64-v3/Compiler/gcccore/python/3.11.5/lib/python3.11/urllib/request.py", line 496, in _call_chain
    result = func(*args)
             ^^^^^^^^^^^
  File "/cvmfs/soft.computecanada.ca/easybuild/software/2023/x86-64-v3/Compiler/gcccore/python/3.11.5/lib/python3.11/urllib/request.py", line 1377, in http_open
    return self.do_open(http.client.HTTPConnection, req)
           ^^^^^^^^^^^^^^^^^^^^^^^^^^^^^^^^^^^^^^^^^^^^^
  File "/cvmfs/soft.computecanada.ca/easybuild/software/2023/x86-64-v3/Compiler/gcccore/python/3.11.5/lib/python3.11/urllib/request.py", line 1352, in do_open
    r = h.getresponse()
        ^^^^^^^^^^^^^^^
  File "/cvmfs/soft.computecanada.ca/easybuild/software/2023/x86-64-v3/Compiler/gcccore/python/3.11.5/lib/python3.11/http/client.py", line 1378, in getresponse
    response.begin()
  File "/cvmfs/soft.computecanada.ca/easybuild/software/2023/x86-64-v3/Compiler/gcccore/python/3.11.5/lib/python3.11/http/client.py", line 318, in begin
    version, status, reason = self._read_status()
                              ^^^^^^^^^^^^^^^^^^^
  File "/cvmfs/soft.computecanada.ca/easybuild/software/2023/x86-64-v3/Compiler/gcccore/python/3.11.5/lib/python3.11/http/client.py", line 287, in _read_status
    raise RemoteDisconnected("Remote end closed connection without"
http.client.RemoteDisconnected: Remote end closed connection without response

During handling of the above exception, another exception occurred:

Traceback (most recent call last):
  File "/cvmfs/soft.computecanada.ca/easybuild/software/2023/x86-64-v3/Compiler/gcccore/python/3.11.5/lib/python3.11/urllib/request.py", line 1348, in do_open
    h.request(req.get_method(), req.selector, req.data, headers,
  File "/cvmfs/soft.computecanada.ca/easybuild/software/2023/x86-64-v3/Compiler/gcccore/python/3.11.5/lib/python3.11/http/client.py", line 1286, in request
    self._send_request(method, url, body, headers, encode_chunked)
  File "/cvmfs/soft.computecanada.ca/easybuild/software/2023/x86-64-v3/Compiler/gcccore/python/3.11.5/lib/python3.11/http/client.py", line 1332, in _send_request
    self.endheaders(body, encode_chunked=encode_chunked)
  File "/cvmfs/soft.computecanada.ca/easybuild/software/2023/x86-64-v3/Compiler/gcccore/python/3.11.5/lib/python3.11/http/client.py", line 1281, in endheaders
    self._send_output(message_body, encode_chunked=encode_chunked)
  File "/cvmfs/soft.computecanada.ca/easybuild/software/2023/x86-64-v3/Compiler/gcccore/python/3.11.5/lib/python3.11/http/client.py", line 1041, in _send_output
    self.send(msg)
  File "/cvmfs/soft.computecanada.ca/easybuild/software/2023/x86-64-v3/Compiler/gcccore/python/3.11.5/lib/python3.11/http/client.py", line 979, in send
    self.connect()
  File "/cvmfs/soft.computecanada.ca/easybuild/software/2023/x86-64-v3/Compiler/gcccore/python/3.11.5/lib/python3.11/http/client.py", line 945, in connect
    self.sock = self._create_connection(
                ^^^^^^^^^^^^^^^^^^^^^^^^
  File "/cvmfs/soft.computecanada.ca/easybuild/software/2023/x86-64-v3/Compiler/gcccore/python/3.11.5/lib/python3.11/socket.py", line 851, in create_connection
    raise exceptions[0]
  File "/cvmfs/soft.computecanada.ca/easybuild/software/2023/x86-64-v3/Compiler/gcccore/python/3.11.5/lib/python3.11/socket.py", line 836, in create_connection
    sock.connect(sa)
ConnectionRefusedError: [Errno 111] Connection refused

During handling of the above exception, another exception occurred:

Traceback (most recent call last):
  File "/lustre06/project/6045755/omij/Chatbot-Resources/benchmark/kg/kg/kg.py", line 468, in shoot_custom_query
    caching_answer = sparql.query().convert()
                     ^^^^^^^^^^^^^^
  File "/home/omij/.local/lib/python3.11/site-packages/SPARQLWrapper/Wrapper.py", line 960, in query
    return QueryResult(self._query())
                       ^^^^^^^^^^^^^
  File "/home/omij/.local/lib/python3.11/site-packages/SPARQLWrapper/Wrapper.py", line 926, in _query
    response = urlopener(request)
               ^^^^^^^^^^^^^^^^^^
  File "/cvmfs/soft.computecanada.ca/easybuild/software/2023/x86-64-v3/Compiler/gcccore/python/3.11.5/lib/python3.11/urllib/request.py", line 216, in urlopen
    return opener.open(url, data, timeout)
           ^^^^^^^^^^^^^^^^^^^^^^^^^^^^^^^
  File "/cvmfs/soft.computecanada.ca/easybuild/software/2023/x86-64-v3/Compiler/gcccore/python/3.11.5/lib/python3.11/urllib/request.py", line 519, in open
    response = self._open(req, data)
               ^^^^^^^^^^^^^^^^^^^^^
  File "/cvmfs/soft.computecanada.ca/easybuild/software/2023/x86-64-v3/Compiler/gcccore/python/3.11.5/lib/python3.11/urllib/request.py", line 536, in _open
    result = self._call_chain(self.handle_open, protocol, protocol +
             ^^^^^^^^^^^^^^^^^^^^^^^^^^^^^^^^^^^^^^^^^^^^^^^^^^^^^^^
  File "/cvmfs/soft.computecanada.ca/easybuild/software/2023/x86-64-v3/Compiler/gcccore/python/3.11.5/lib/python3.11/urllib/request.py", line 496, in _call_chain
    result = func(*args)
             ^^^^^^^^^^^
  File "/cvmfs/soft.computecanada.ca/easybuild/software/2023/x86-64-v3/Compiler/gcccore/python/3.11.5/lib/python3.11/urllib/request.py", line 1377, in http_open
    return self.do_open(http.client.HTTPConnection, req)
           ^^^^^^^^^^^^^^^^^^^^^^^^^^^^^^^^^^^^^^^^^^^^^
  File "/cvmfs/soft.computecanada.ca/easybuild/software/2023/x86-64-v3/Compiler/gcccore/python/3.11.5/lib/python3.11/urllib/request.py", line 1351, in do_open
    raise URLError(err)
urllib.error.URLError: <urlopen error [Errno 111] Connection refused>
2024-06-11 23:50:37,288 - logger - ERROR - Error occurred while extracting subgraph: kg.kg.kg.SparqlQueryResponse() argument after ** must be a mapping, not NoneType
Traceback (most recent call last):
  File "/lustre06/project/6045755/omij/Chatbot-Resources/benchmark/kg/kg/kg.py", line 534, in subgraph_extractor
    q_response = SparqlQueryResponse(**result)
                 ^^^^^^^^^^^^^^^^^^^^^^^^^^^^^
TypeError: kg.kg.kg.SparqlQueryResponse() argument after ** must be a mapping, not NoneType
2024-06-11 23:52:59,223 - logger - ERROR - Error occurred while executing custom query: <urlopen error [Errno 111] Connection refused>
Traceback (most recent call last):
  File "/lustre06/project/6045755/omij/Chatbot-Resources/benchmark/kg/kg/kg.py", line 463, in shoot_custom_query
    caching_answer = sparql.query().convert()
                     ^^^^^^^^^^^^^^
  File "/home/omij/.local/lib/python3.11/site-packages/SPARQLWrapper/Wrapper.py", line 960, in query
    return QueryResult(self._query())
                       ^^^^^^^^^^^^^
  File "/home/omij/.local/lib/python3.11/site-packages/SPARQLWrapper/Wrapper.py", line 926, in _query
    response = urlopener(request)
               ^^^^^^^^^^^^^^^^^^
  File "/cvmfs/soft.computecanada.ca/easybuild/software/2023/x86-64-v3/Compiler/gcccore/python/3.11.5/lib/python3.11/urllib/request.py", line 216, in urlopen
    return opener.open(url, data, timeout)
           ^^^^^^^^^^^^^^^^^^^^^^^^^^^^^^^
  File "/cvmfs/soft.computecanada.ca/easybuild/software/2023/x86-64-v3/Compiler/gcccore/python/3.11.5/lib/python3.11/urllib/request.py", line 519, in open
    response = self._open(req, data)
               ^^^^^^^^^^^^^^^^^^^^^
  File "/cvmfs/soft.computecanada.ca/easybuild/software/2023/x86-64-v3/Compiler/gcccore/python/3.11.5/lib/python3.11/urllib/request.py", line 536, in _open
    result = self._call_chain(self.handle_open, protocol, protocol +
             ^^^^^^^^^^^^^^^^^^^^^^^^^^^^^^^^^^^^^^^^^^^^^^^^^^^^^^^
  File "/cvmfs/soft.computecanada.ca/easybuild/software/2023/x86-64-v3/Compiler/gcccore/python/3.11.5/lib/python3.11/urllib/request.py", line 496, in _call_chain
    result = func(*args)
             ^^^^^^^^^^^
  File "/cvmfs/soft.computecanada.ca/easybuild/software/2023/x86-64-v3/Compiler/gcccore/python/3.11.5/lib/python3.11/urllib/request.py", line 1377, in http_open
    return self.do_open(http.client.HTTPConnection, req)
           ^^^^^^^^^^^^^^^^^^^^^^^^^^^^^^^^^^^^^^^^^^^^^
  File "/cvmfs/soft.computecanada.ca/easybuild/software/2023/x86-64-v3/Compiler/gcccore/python/3.11.5/lib/python3.11/urllib/request.py", line 1352, in do_open
    r = h.getresponse()
        ^^^^^^^^^^^^^^^
  File "/cvmfs/soft.computecanada.ca/easybuild/software/2023/x86-64-v3/Compiler/gcccore/python/3.11.5/lib/python3.11/http/client.py", line 1378, in getresponse
    response.begin()
  File "/cvmfs/soft.computecanada.ca/easybuild/software/2023/x86-64-v3/Compiler/gcccore/python/3.11.5/lib/python3.11/http/client.py", line 318, in begin
    version, status, reason = self._read_status()
                              ^^^^^^^^^^^^^^^^^^^
  File "/cvmfs/soft.computecanada.ca/easybuild/software/2023/x86-64-v3/Compiler/gcccore/python/3.11.5/lib/python3.11/http/client.py", line 287, in _read_status
    raise RemoteDisconnected("Remote end closed connection without"
http.client.RemoteDisconnected: Remote end closed connection without response

During handling of the above exception, another exception occurred:

Traceback (most recent call last):
  File "/cvmfs/soft.computecanada.ca/easybuild/software/2023/x86-64-v3/Compiler/gcccore/python/3.11.5/lib/python3.11/urllib/request.py", line 1348, in do_open
    h.request(req.get_method(), req.selector, req.data, headers,
  File "/cvmfs/soft.computecanada.ca/easybuild/software/2023/x86-64-v3/Compiler/gcccore/python/3.11.5/lib/python3.11/http/client.py", line 1286, in request
    self._send_request(method, url, body, headers, encode_chunked)
  File "/cvmfs/soft.computecanada.ca/easybuild/software/2023/x86-64-v3/Compiler/gcccore/python/3.11.5/lib/python3.11/http/client.py", line 1332, in _send_request
    self.endheaders(body, encode_chunked=encode_chunked)
  File "/cvmfs/soft.computecanada.ca/easybuild/software/2023/x86-64-v3/Compiler/gcccore/python/3.11.5/lib/python3.11/http/client.py", line 1281, in endheaders
    self._send_output(message_body, encode_chunked=encode_chunked)
  File "/cvmfs/soft.computecanada.ca/easybuild/software/2023/x86-64-v3/Compiler/gcccore/python/3.11.5/lib/python3.11/http/client.py", line 1041, in _send_output
    self.send(msg)
  File "/cvmfs/soft.computecanada.ca/easybuild/software/2023/x86-64-v3/Compiler/gcccore/python/3.11.5/lib/python3.11/http/client.py", line 979, in send
    self.connect()
  File "/cvmfs/soft.computecanada.ca/easybuild/software/2023/x86-64-v3/Compiler/gcccore/python/3.11.5/lib/python3.11/http/client.py", line 945, in connect
    self.sock = self._create_connection(
                ^^^^^^^^^^^^^^^^^^^^^^^^
  File "/cvmfs/soft.computecanada.ca/easybuild/software/2023/x86-64-v3/Compiler/gcccore/python/3.11.5/lib/python3.11/socket.py", line 851, in create_connection
    raise exceptions[0]
  File "/cvmfs/soft.computecanada.ca/easybuild/software/2023/x86-64-v3/Compiler/gcccore/python/3.11.5/lib/python3.11/socket.py", line 836, in create_connection
    sock.connect(sa)
ConnectionRefusedError: [Errno 111] Connection refused

During handling of the above exception, another exception occurred:

Traceback (most recent call last):
  File "/lustre06/project/6045755/omij/Chatbot-Resources/benchmark/kg/kg/kg.py", line 468, in shoot_custom_query
    caching_answer = sparql.query().convert()
                     ^^^^^^^^^^^^^^
  File "/home/omij/.local/lib/python3.11/site-packages/SPARQLWrapper/Wrapper.py", line 960, in query
    return QueryResult(self._query())
                       ^^^^^^^^^^^^^
  File "/home/omij/.local/lib/python3.11/site-packages/SPARQLWrapper/Wrapper.py", line 926, in _query
    response = urlopener(request)
               ^^^^^^^^^^^^^^^^^^
  File "/cvmfs/soft.computecanada.ca/easybuild/software/2023/x86-64-v3/Compiler/gcccore/python/3.11.5/lib/python3.11/urllib/request.py", line 216, in urlopen
    return opener.open(url, data, timeout)
           ^^^^^^^^^^^^^^^^^^^^^^^^^^^^^^^
  File "/cvmfs/soft.computecanada.ca/easybuild/software/2023/x86-64-v3/Compiler/gcccore/python/3.11.5/lib/python3.11/urllib/request.py", line 519, in open
    response = self._open(req, data)
               ^^^^^^^^^^^^^^^^^^^^^
  File "/cvmfs/soft.computecanada.ca/easybuild/software/2023/x86-64-v3/Compiler/gcccore/python/3.11.5/lib/python3.11/urllib/request.py", line 536, in _open
    result = self._call_chain(self.handle_open, protocol, protocol +
             ^^^^^^^^^^^^^^^^^^^^^^^^^^^^^^^^^^^^^^^^^^^^^^^^^^^^^^^
  File "/cvmfs/soft.computecanada.ca/easybuild/software/2023/x86-64-v3/Compiler/gcccore/python/3.11.5/lib/python3.11/urllib/request.py", line 496, in _call_chain
    result = func(*args)
             ^^^^^^^^^^^
  File "/cvmfs/soft.computecanada.ca/easybuild/software/2023/x86-64-v3/Compiler/gcccore/python/3.11.5/lib/python3.11/urllib/request.py", line 1377, in http_open
    return self.do_open(http.client.HTTPConnection, req)
           ^^^^^^^^^^^^^^^^^^^^^^^^^^^^^^^^^^^^^^^^^^^^^
  File "/cvmfs/soft.computecanada.ca/easybuild/software/2023/x86-64-v3/Compiler/gcccore/python/3.11.5/lib/python3.11/urllib/request.py", line 1351, in do_open
    raise URLError(err)
urllib.error.URLError: <urlopen error [Errno 111] Connection refused>
2024-06-11 23:52:59,235 - logger - ERROR - Error occurred while extracting subgraph: kg.kg.kg.SparqlQueryResponse() argument after ** must be a mapping, not NoneType
Traceback (most recent call last):
  File "/lustre06/project/6045755/omij/Chatbot-Resources/benchmark/kg/kg/kg.py", line 534, in subgraph_extractor
    q_response = SparqlQueryResponse(**result)
                 ^^^^^^^^^^^^^^^^^^^^^^^^^^^^^
TypeError: kg.kg.kg.SparqlQueryResponse() argument after ** must be a mapping, not NoneType
2024-06-12 00:07:35,599 - logger - ERROR - Error occurred while executing custom query: <urlopen error [Errno 111] Connection refused>
Traceback (most recent call last):
  File "/lustre06/project/6045755/omij/Chatbot-Resources/benchmark/kg/kg/kg.py", line 463, in shoot_custom_query
    caching_answer = sparql.query().convert()
                     ^^^^^^^^^^^^^^
  File "/home/omij/.local/lib/python3.11/site-packages/SPARQLWrapper/Wrapper.py", line 960, in query
    return QueryResult(self._query())
                       ^^^^^^^^^^^^^
  File "/home/omij/.local/lib/python3.11/site-packages/SPARQLWrapper/Wrapper.py", line 926, in _query
    response = urlopener(request)
               ^^^^^^^^^^^^^^^^^^
  File "/cvmfs/soft.computecanada.ca/easybuild/software/2023/x86-64-v3/Compiler/gcccore/python/3.11.5/lib/python3.11/urllib/request.py", line 216, in urlopen
    return opener.open(url, data, timeout)
           ^^^^^^^^^^^^^^^^^^^^^^^^^^^^^^^
  File "/cvmfs/soft.computecanada.ca/easybuild/software/2023/x86-64-v3/Compiler/gcccore/python/3.11.5/lib/python3.11/urllib/request.py", line 519, in open
    response = self._open(req, data)
               ^^^^^^^^^^^^^^^^^^^^^
  File "/cvmfs/soft.computecanada.ca/easybuild/software/2023/x86-64-v3/Compiler/gcccore/python/3.11.5/lib/python3.11/urllib/request.py", line 536, in _open
    result = self._call_chain(self.handle_open, protocol, protocol +
             ^^^^^^^^^^^^^^^^^^^^^^^^^^^^^^^^^^^^^^^^^^^^^^^^^^^^^^^
  File "/cvmfs/soft.computecanada.ca/easybuild/software/2023/x86-64-v3/Compiler/gcccore/python/3.11.5/lib/python3.11/urllib/request.py", line 496, in _call_chain
    result = func(*args)
             ^^^^^^^^^^^
  File "/cvmfs/soft.computecanada.ca/easybuild/software/2023/x86-64-v3/Compiler/gcccore/python/3.11.5/lib/python3.11/urllib/request.py", line 1377, in http_open
    return self.do_open(http.client.HTTPConnection, req)
           ^^^^^^^^^^^^^^^^^^^^^^^^^^^^^^^^^^^^^^^^^^^^^
  File "/cvmfs/soft.computecanada.ca/easybuild/software/2023/x86-64-v3/Compiler/gcccore/python/3.11.5/lib/python3.11/urllib/request.py", line 1352, in do_open
    r = h.getresponse()
        ^^^^^^^^^^^^^^^
  File "/cvmfs/soft.computecanada.ca/easybuild/software/2023/x86-64-v3/Compiler/gcccore/python/3.11.5/lib/python3.11/http/client.py", line 1378, in getresponse
    response.begin()
  File "/cvmfs/soft.computecanada.ca/easybuild/software/2023/x86-64-v3/Compiler/gcccore/python/3.11.5/lib/python3.11/http/client.py", line 318, in begin
    version, status, reason = self._read_status()
                              ^^^^^^^^^^^^^^^^^^^
  File "/cvmfs/soft.computecanada.ca/easybuild/software/2023/x86-64-v3/Compiler/gcccore/python/3.11.5/lib/python3.11/http/client.py", line 287, in _read_status
    raise RemoteDisconnected("Remote end closed connection without"
http.client.RemoteDisconnected: Remote end closed connection without response

During handling of the above exception, another exception occurred:

Traceback (most recent call last):
  File "/cvmfs/soft.computecanada.ca/easybuild/software/2023/x86-64-v3/Compiler/gcccore/python/3.11.5/lib/python3.11/urllib/request.py", line 1348, in do_open
    h.request(req.get_method(), req.selector, req.data, headers,
  File "/cvmfs/soft.computecanada.ca/easybuild/software/2023/x86-64-v3/Compiler/gcccore/python/3.11.5/lib/python3.11/http/client.py", line 1286, in request
    self._send_request(method, url, body, headers, encode_chunked)
  File "/cvmfs/soft.computecanada.ca/easybuild/software/2023/x86-64-v3/Compiler/gcccore/python/3.11.5/lib/python3.11/http/client.py", line 1332, in _send_request
    self.endheaders(body, encode_chunked=encode_chunked)
  File "/cvmfs/soft.computecanada.ca/easybuild/software/2023/x86-64-v3/Compiler/gcccore/python/3.11.5/lib/python3.11/http/client.py", line 1281, in endheaders
    self._send_output(message_body, encode_chunked=encode_chunked)
  File "/cvmfs/soft.computecanada.ca/easybuild/software/2023/x86-64-v3/Compiler/gcccore/python/3.11.5/lib/python3.11/http/client.py", line 1041, in _send_output
    self.send(msg)
  File "/cvmfs/soft.computecanada.ca/easybuild/software/2023/x86-64-v3/Compiler/gcccore/python/3.11.5/lib/python3.11/http/client.py", line 979, in send
    self.connect()
  File "/cvmfs/soft.computecanada.ca/easybuild/software/2023/x86-64-v3/Compiler/gcccore/python/3.11.5/lib/python3.11/http/client.py", line 945, in connect
    self.sock = self._create_connection(
                ^^^^^^^^^^^^^^^^^^^^^^^^
  File "/cvmfs/soft.computecanada.ca/easybuild/software/2023/x86-64-v3/Compiler/gcccore/python/3.11.5/lib/python3.11/socket.py", line 851, in create_connection
    raise exceptions[0]
  File "/cvmfs/soft.computecanada.ca/easybuild/software/2023/x86-64-v3/Compiler/gcccore/python/3.11.5/lib/python3.11/socket.py", line 836, in create_connection
    sock.connect(sa)
ConnectionRefusedError: [Errno 111] Connection refused

During handling of the above exception, another exception occurred:

Traceback (most recent call last):
  File "/lustre06/project/6045755/omij/Chatbot-Resources/benchmark/kg/kg/kg.py", line 468, in shoot_custom_query
    caching_answer = sparql.query().convert()
                     ^^^^^^^^^^^^^^
  File "/home/omij/.local/lib/python3.11/site-packages/SPARQLWrapper/Wrapper.py", line 960, in query
    return QueryResult(self._query())
                       ^^^^^^^^^^^^^
  File "/home/omij/.local/lib/python3.11/site-packages/SPARQLWrapper/Wrapper.py", line 926, in _query
    response = urlopener(request)
               ^^^^^^^^^^^^^^^^^^
  File "/cvmfs/soft.computecanada.ca/easybuild/software/2023/x86-64-v3/Compiler/gcccore/python/3.11.5/lib/python3.11/urllib/request.py", line 216, in urlopen
    return opener.open(url, data, timeout)
           ^^^^^^^^^^^^^^^^^^^^^^^^^^^^^^^
  File "/cvmfs/soft.computecanada.ca/easybuild/software/2023/x86-64-v3/Compiler/gcccore/python/3.11.5/lib/python3.11/urllib/request.py", line 519, in open
    response = self._open(req, data)
               ^^^^^^^^^^^^^^^^^^^^^
  File "/cvmfs/soft.computecanada.ca/easybuild/software/2023/x86-64-v3/Compiler/gcccore/python/3.11.5/lib/python3.11/urllib/request.py", line 536, in _open
    result = self._call_chain(self.handle_open, protocol, protocol +
             ^^^^^^^^^^^^^^^^^^^^^^^^^^^^^^^^^^^^^^^^^^^^^^^^^^^^^^^
  File "/cvmfs/soft.computecanada.ca/easybuild/software/2023/x86-64-v3/Compiler/gcccore/python/3.11.5/lib/python3.11/urllib/request.py", line 496, in _call_chain
    result = func(*args)
             ^^^^^^^^^^^
  File "/cvmfs/soft.computecanada.ca/easybuild/software/2023/x86-64-v3/Compiler/gcccore/python/3.11.5/lib/python3.11/urllib/request.py", line 1377, in http_open
    return self.do_open(http.client.HTTPConnection, req)
           ^^^^^^^^^^^^^^^^^^^^^^^^^^^^^^^^^^^^^^^^^^^^^
  File "/cvmfs/soft.computecanada.ca/easybuild/software/2023/x86-64-v3/Compiler/gcccore/python/3.11.5/lib/python3.11/urllib/request.py", line 1351, in do_open
    raise URLError(err)
urllib.error.URLError: <urlopen error [Errno 111] Connection refused>
2024-06-12 00:07:35,634 - logger - ERROR - Error occurred while extracting subgraph: kg.kg.kg.SparqlQueryResponse() argument after ** must be a mapping, not NoneType
Traceback (most recent call last):
  File "/lustre06/project/6045755/omij/Chatbot-Resources/benchmark/kg/kg/kg.py", line 502, in subgraph_extractor
    q_response = SparqlQueryResponse(**result)
                 ^^^^^^^^^^^^^^^^^^^^^^^^^^^^^
TypeError: kg.kg.kg.SparqlQueryResponse() argument after ** must be a mapping, not NoneType
